Workbook

Sheet Read me
A1: FortiSIEM 7.6.0 rule catalogue: identity, AD, Kerberos, AD CS, credential access, lateral movement, privilege change
A3: Source
A4: Rule pages: https://filestore.fortinet.com/docs.fortinet.com/fsiem/Public_Resource_Access/7_6_0/rules/rule_descriptions.htm (index) plus one page per rule. All 3,857 rule pages fetched on 2026-10-05, single-threaded at about 4 requests/s, cached locally, 0 failures, 0 parse errors.
A5: Rule lists: 760-new-itdr-rules.pdf (57), 760-existing-rules-added-to-itdr.pdf (244), 760-new-rules.pdf (1,041), linked from "What's New in 7.6.0". All 301 ITDR names matched a rule page.
A6: Sizing compared: ITDR log sizing dashboard (claude.ai/artifact/QdAN6guArhemD2qmo1HAVr) and worst-case calculator (claude.ai/artifact/HKjRytjases9eu6exWE6Th), both read on 2026-10-05.
A8: Sheets
A9: Catalogue: 999 in-scope rules, one row each. Sorted new ITDR, then re-tagged ITDR, then identity-core, then tactic-only.
A10: Subpatterns: one row per subpattern with its full query, event types, filters, group-by, aggregate.
A11: Rule-Event map / Rule-DS map / Rule-Row map: long-format helpers the summary formulas count from. Rule-Row map holds one row per distinct rule and sizing row, so sizing-row counts are distinct rules.
A12: Data sources: rules and event types per FortiSIEM data source (counts are live COUNTIFS formulas).
A13: Log channels: rules per log channel and event ID, mapped to your sizing rows.
A14: Coverage - 57 ITDR: each new ITDR rule, what your dashboard assumed, what the rule actually reads, and a verdict.
... A37: This reflects the public rule documentation for 7.6.0 as published on 2026-10-05. Content updates after that date may change rules. Event-type groups and the Event Hub parser routing (MicrosoftAzureEntraParser vs AzureEventHubParser) are not visible in the docs and should be checked in a live 7.6.0 system under Resources > Event Types and on a sample of ingested events.

Sheet Catalogue
A1: Rule ID | B1: Rule name | C1: ITDR status | D1: Scope class | E1: Scope tags | F1: Default status | G1: Severity | H1: Severity label | I1: Category | J1: Detection technology | K1: Rule mode | L1: MITRE tactics | M1: MITRE techniques | N1: FortiSIEM data source(s) | O1: Event types (all subpatterns) | P1: Excluded event types | Q1: # subpatterns | R1: Subpattern logic | S1: Filters (non-eventType conditions) | T1: Group-by attributes | U1: Aggregate constraint(s) | V1: Time window (s) | W1: Global constraint | X1: Log channel : event key (derived) | Y1: Sizing row(s) that carry it (derived) | Z1: Description | AA1: Rule page
A2: PH_Rule_Azure_Entra_ID_Conditional_Access_Disabled | B2: Azure Entra ID: Conditional Access Disabled | C2: New ITDR (7.6.0) | D2: Identity-core | E2: Entra ID, Privilege/account change | F2: Enabled | G2: 9 | H2: High | I2: Security | J2: Correlation | K2: Streaming | L2: Defense Evasion | M2: T1556.001 | N2: Microsoft Entra Activity Logs via Azure Event Hub | O2: MS-Entra-AuditLogs-Policy-Update_policy-success | Q2: 1 | R2: Filter | S2: opName REGEXP ".*(?:Delete conditional access policy|Update conditional access policy).*" | T2: user,opName | U2: COUNT(*) >= 1 | V2: 300 | X2: Entra Event Hub: AuditLogs | Y2: ea | Z2: Detects when a Conditional Access policy is disabled, modified, or deleted. An adversary may modify or remove Conditional Access policies to weaken authentication requirements and bypass security controls. | AA2: https://filestore.fortinet.com/docs.fortinet.com/fsiem/Public_Resource_Access/7_6_0/rules/PH_RULE_Azure_Entra_ID_Conditional_Access_Disabled.htm
A3: PH_Rule_Azure_Entra_ID_Domain_Authentication_Changed | B3: Azure Entra ID: Domain Authentication Changed | C3: New ITDR (7.6.0) | D3: Identity-core | E3: Entra ID, Privilege/account change | F3: Enabled | G3: 10 | H3: High | I3: Security | J3: Correlation | K3: Streaming | L3: Defense Evasion | M3: T1484.002 | N3: Microsoft Entra Activity Logs via Azure Event Hub | O3: MS-Entra-AuditLogs-DirectoryMgmt-Set_domain_authentication-success | Q3: 1 | R3: Filter | S3: — | T3: user,opName,targetDomain | U3: COUNT(*) >= 1 | V3: 300 | X3: Entra Event Hub: AuditLogs | Y3: ea | Z3: Detects when domain authentication settings are modified in Microsoft Entra ID, including switching a domain between managed and federated authentication. An adversary may change domain authentication to redirect authentication to an attacker-controlled identity provider, allowing them to sign in as any user in that domain using forged tokens. This is a known technique for tenant backdooring and persistence. Legitimate administrative activity, approved change windows, service accounts, and known admin tools can also trigger this rule; tune known administrative activity before enabling in production. | AA3: https://filestore.fortinet.com/docs.fortinet.com/fsiem/Public_Resource_Access/7_6_0/rules/PH_RULE_Azure_Entra_ID_Domain_Authentication_Changed.htm
A4: PH_Rule_Azure_Entra_ID_External_User_Added_To_Privileged_Group | B4: Azure Entra ID: External User Added To Privileged Group | C4: New ITDR (7.6.0) | D4: Identity-core | E4: Entra ID, Privilege/account change | F4: Enabled | G4: 8 | H4: Medium | I4: Security | J4: Correlation | K4: Streaming | L4: Persistence | M4: T1098.007 | N4: Microsoft Entra Activity Logs via Azure Event Hub | O4: MS-Entra-AuditLogs-GroupMgmt-Add_member_to_group-success | Q4: 1 | R4: Filter | S4: targetUser CONTAIN "#EXT#" AND groupName CONTAIN "Admin" | T4: user,targetUser,opName,groupName | U4: COUNT(*) >= 1 | V4: 300 | X4: Entra Event Hub: AuditLogs | Y4: ea | Z4: Detects when a guest or external user is added to a group that contains the string "Admin" in Microsoft Entra ID. While adding external users to groups is a routine collaboration activity, adding a guest to a privileged or sensitive group may indicate persistence, privilege escalation, or an attempt to bypass tenant controls by using an outside account. Legitimate B2B collaboration, approved partner onboarding, and known administrative tools can also trigger this rule; tune known administrative activity and approved guest onboarding workflows before enabling in production. | AA4: https://filestore.fortinet.com/docs.fortinet.com/fsiem/Public_Resource_Access/7_6_0/rules/PH_RULE_Azure_Entra_ID_External_User_Added_To_Privileged_Group.htm
A5: PH_Rule_Azure_Entra_ID_MFA_Bypass | B5: Azure Entra ID: MFA Bypass Or Satisfied By Claim | C5: New ITDR (7.6.0) | D5: Identity-core | E5: Entra ID, Credential Access, Privilege/account change | F5: Enabled | G5: 9 | H5: High | I5: Security | J5: Correlation | K5: Streaming | L5: Credential Access | M5: T1556.001 | N5: Microsoft Entra Activity Logs via Azure Event Hub | O5: MS-Entra-SignInLogs-Logon-success | Q5: 1 | R5: Filter | S5: statusDetailedReason REGEXP ".*(?:bypassed|satisfied by claim|not required).*" | T5: user,srcIpAddr,appName,policyStatus | U5: COUNT(*) >= 1 | V5: 300 | X5: Entra Event Hub: SignInLogs (interactive) | Y5: ei | Z5: Detects sign-in events where MFA was bypassed or satisfied by an unexpected claim. Adversaries may modify authentication processes to bypass MFA requirements, allowing unauthorized access without the second factor. | AA5: https://filestore.fortinet.com/docs.fortinet.com/fsiem/Public_Resource_Access/7_6_0/rules/PH_RULE_Azure_Entra_ID_MFA_Bypass.htm
A6: PH_Rule_Azure_Entra_ID_New_Federation_Domain_Added | B6: Azure Entra ID: New Federation Domain Added | C6: New ITDR (7.6.0) | D6: Identity-core | E6: Entra ID, Active Directory, Privilege/account change | F6: Enabled | G6: 10 | H6: High | I6: Security | J6: Correlation | K6: Streaming | L6: Defense Evasion | M6: T1484.002 | N6: Microsoft Entra Activity Logs via Azure Event Hub | O6: MS-Entra-AuditLogs-DirectoryMgmt-Set_federation_settings_on_domain-success | Q6: 1 | R6: Filter | S6: — | T6: user,opName,targetDomain | U6: COUNT(*) >= 1 | V6: 300 | X6: Entra Event Hub: AuditLogs | Y6: ea | Z6: Detects when federation settings are configured on a domain in Microsoft Entra ID. Adversaries may add or modify federation settings to establish an attacker-controlled identity provider for a legitimate domain, allowing them to sign in as any user in the tenant using forged tokens. This is a known technique for persistence and privilege escalation (e.g., Azure AD backdoor federation). Legitimate administrative activity, approved change windows, service accounts, and known admin tools can also trigger this rule; tune known administrative activity before enabling in production. | AA6: https://filestore.fortinet.com/docs.fortinet.com/fsiem/Public_Resource_Access/7_6_0/rules/PH_RULE_Azure_Entra_ID_New_Federation_Domain_Added.htm
A7: PH_Rule_Azure_Entra_ID_OAuth_Secret_Added | B7: Azure Entra ID: OAuth Secret Added | C7: New ITDR (7.6.0) | D7: Identity-core | E7: Entra ID, Privilege/account change | F7: Enabled | G7: 9 | H7: High | I7: Security | J7: Correlation | K7: Streaming | L7: Persistence | M7: T1098.001 | N7: Microsoft Entra Activity Logs via Azure Event Hub | O7: MS-Entra-AuditLogs-ApplicationMgmt-Add_service_principal_credentials-success MS-Entra-AuditLogs-ApplicationMgmt-Update_application_Certificates_and_secrets_Mgmt-success | Q7: 1 | R7: Filter | S7: — | T7: user,targetUser,opName | U7: COUNT(*) >= 1 | V7: 300 | X7: Entra Event Hub: AuditLogs | Y7: ea | Z7: Detects when a credential or secret is added to an OAuth application or service principal. An adversary may add credentials to an application or service principal to establish persistence and access resources using the application's permissions. | AA7: https://filestore.fortinet.com/docs.fortinet.com/fsiem/Public_Resource_Access/7_6_0/rules/PH_RULE_Azure_Entra_ID_OAuth_Secret_Added.htm
A8: PH_Rule_Azure_Entra_ID_User_Added_To_Application_Admin | B8: Azure Entra ID: User Added To Application Admin | C8: New ITDR (7.6.0) | D8: Identity-core | E8: Entra ID, Privilege/account change | F8: Enabled | G8: 9 | H8: High | I8: Security | J8: Correlation | K8: Streaming | L8: Persistence | M8: T1098.003 | N8: Microsoft Entra Activity Logs via Azure Event Hub | O8: MS-Entra-AuditLogs-RoleMgmt-Add_member_to_role-success | Q8: 1 | R8: Filter | S8: role = "Application Administrator" | T8: user,opName,role,targetUser | U8: COUNT(*) >= 1 | V8: 300 | X8: Entra Event Hub: AuditLogs | Y8: ea | Z8: Detects when a user is added to the Application Administrator privileged role in Microsoft Entra ID. An adversary with sufficient privileges may add an account to this role to establish persistence, manage application registrations and service principals, or grant themselves credentials on applications that have sensitive Microsoft Graph permissions. Legitimate administrative activity, approved change windows, service accounts, and known admin tools can also trigger this rule; tune known administrative activity before enabling in production. | AA8: https://filestore.fortinet.com/docs.fortinet.com/fsiem/Public_Resource_Access/7_6_0/rules/PH_RULE_Azure_Entra_ID_User_Added_To_Application_Admin.htm
A9: PH_Rule_Azure_Entra_ID_User_Added_To_Exchange_Admin | B9: Azure Entra ID: User Added To Exchange Admin | C9: New ITDR (7.6.0) | D9: Identity-core | E9: Entra ID, Privilege/account change | F9: Enabled | G9: 9 | H9: High | I9: Security | J9: Correlation | K9: Streaming | L9: Persistence | M9: T1098.003 | N9: Microsoft Entra Activity Logs via Azure Event Hub | O9: MS-Entra-AuditLogs-RoleMgmt-Add_member_to_role-success | Q9: 1 | R9: Filter | S9: role = "Exchange Administrator" | T9: user,opName,role,targetUser | U9: COUNT(*) >= 1 | V9: 300 | X9: Entra Event Hub: AuditLogs | Y9: ea | Z9: Detects when a user is added to the Exchange Administrator role in Microsoft Entra ID. This role can manage all aspects of Exchange Online, including mailboxes, mail flow rules, and transport configuration. An adversary with this role can access email content, create inbox rules for persistence, modify mail flow to intercept or exfiltrate messages, or grant themselves Full Access to any mailbox. Legitimate administrative activity, approved change windows, service accounts, and known admin tools can also trigger this rule; tune known administrative activity before enabling in production. | AA9: https://filestore.fortinet.com/docs.fortinet.com/fsiem/Public_Resource_Access/7_6_0/rules/PH_RULE_Azure_Entra_ID_User_Added_To_Exchange_Admin.htm
A10: PH_Rule_Azure_Entra_ID_User_Added_To_Global_Admin | B10: Azure Entra ID: User Added To Global Admin | C10: New ITDR (7.6.0) | D10: Identity-core | E10: Entra ID, Privilege/account change | F10: Enabled | G10: 10 | H10: High | I10: Security | J10: Correlation | K10: Streaming | L10: Persistence | M10: T1098.003 | N10: Microsoft Entra Activity Logs via Azure Event Hub | O10: MS-Entra-AuditLogs-RoleMgmt-Add_member_to_role-success | Q10: 1 | R10: Filter | S10: role = "Global Administrator" | T10: user,opName,role,targetUser | U10: COUNT(*) >= 1 | V10: 300 | X10: Entra Event Hub: AuditLogs | Y10: ea | Z10: Detects when a user is added to the Global Administrator role in Microsoft Entra ID. This is the most powerful role in Entra ID, providing full access to all administrative features across Microsoft 365 and Azure services. An adversary with this role can perform any administrative action, including managing security controls, accessing all data, creating new admin accounts, and resetting user credentials. Legitimate administrative activity, approved change windows, service accounts, and known admin tools can also trigger this rule; tune known administrative activity before enabling in production. | AA10: https://filestore.fortinet.com/docs.fortinet.com/fsiem/Public_Resource_Access/7_6_0/rules/PH_RULE_Azure_Entra_ID_User_Added_To_Global_Admin.htm
A11: PH_Rule_Azure_Entra_ID_User_Added_To_Privileged_Role_Admin | B11: Azure Entra ID: User Added To Privileged Role Admin | C11: New ITDR (7.6.0) | D11: Identity-core | E11: Entra ID, Privilege/account change | F11: Enabled | G11: 10 | H11: High | I11: Security | J11: Correlation | K11: Streaming | L11: Persistence | M11: T1098.003 | N11: Microsoft Entra Activity Logs via Azure Event Hub | O11: MS-Entra-AuditLogs-RoleMgmt-Add_member_to_role-success | Q11: 1 | R11: Filter | S11: role = "Privileged Role Administrator" | T11: user,opName,role,targetUser | U11: COUNT(*) >= 1 | V11: 300 | X11: Entra Event Hub: AuditLogs | Y11: ea | Z11: Detects when a user is added to the Privileged Administrator role in Microsoft Entra ID. This role can manage all role assignments in Entra ID, including Global Administrator, and is among the most sensitive privileged roles in the tenant. An adversary with control of this role can escalate themselves or others to any privileged role. Legitimate administrative activity, approved change windows, service accounts, and known admin tools can also trigger this rule; tune known administrative activity before enabling in production. | AA11: https://filestore.fortinet.com/docs.fortinet.com/fsiem/Public_Resource_Access/7_6_0/rules/PH_RULE_Azure_Entra_ID_User_Added_To_Privileged_Role_Admin.htm
A12: PH_Rule_Azure_Entra_ID_User_Added_To_Security_Admin | B12: Azure Entra ID: User Added To Security Admin | C12: New ITDR (7.6.0) | D12: Identity-core | E12: Entra ID, Privilege/account change | F12: Enabled | G12: 9 | H12: High | I12: Security | J12: Correlation | K12: Streaming | L12: Persistence | M12: T1098.003 | N12: Microsoft Entra Activity Logs via Azure Event Hub | O12: MS-Entra-AuditLogs-RoleMgmt-Add_member_to_role-success | Q12: 1 | R12: Filter | S12: role = "Security Administrator" | T12: user,opName,role,targetUser | U12: COUNT(*) >= 1 | V12: 300 | X12: Entra Event Hub: AuditLogs | Y12: ea | Z12: Detects when a user is added to the Security Administrator role in Microsoft Entra ID. This role can read all security-related information, manage security configuration, and grant administrative access to other security tools. An adversary with this role can tamper with security controls, alter alerts, or disable security monitoring. Legitimate administrative activity, approved change windows, service accounts, and known admin tools can also trigger this rule; tune known administrative activity before enabling in production. | AA12: https://filestore.fortinet.com/docs.fortinet.com/fsiem/Public_Resource_Access/7_6_0/rules/PH_RULE_Azure_Entra_ID_User_Added_To_Security_Admin.htm
A13: PH_Rule_Linux_etc_shadow_access | B13: Linux: /etc/shadow Access | C13: New ITDR (7.6.0) | D13: Identity-core | E13: Credential Access | F13: Enabled | G13: 9 | H13: High | I13: Security | J13: Correlation | K13: Streaming | L13: Credential Access | M13: T1003.008 | N13: Linux Process Monitoring via Linux Collector | O13: LINUX_Auditd_PATH LINUX_Auditd_SYSCALL LINUX_PROCESS_EXEC | Q13: 1 | R13: Filter | S13: (osObjName="/etc/shadow" OR command REGEXP ".*(?:/etc/shadow|unshadow).*") | T13: hostName,user,procName,command,osObjName | U13: COUNT(*) >= 1 | V13: 300 | X13: Linux Collector: LINUX_Auditd_PATH Linux Collector: LINUX_Auditd_SYSCALL Linux Collector: LINUX_PROCESS_EXEC | Z13: Detects reads or copies of /etc/shadow. The /etc/shadow file stores hashed passwords and is only readable by root. Access by unauthorized users or tools like unshadow may indicate credential dumping activity. | AA13: https://filestore.fortinet.com/docs.fortinet.com/fsiem/Public_Resource_Access/7_6_0/rules/PH_RULE_Linux_etc_shadow_access.htm
A14: PH_Rule_Linux_Root_Equivalent_Account_Command | B14: Linux: Attempt to Create or Modify a Root-Equivalent Account | C14: New ITDR (7.6.0) | D14: Identity-core | E14: Privilege/account change | F14: Enabled | G14: 9 | H14: High | I14: Security | J14: Event-Based | K14: Streaming | L14: Persistence | M14: T1136.001 | N14: Linux Process Monitoring via Linux Collector | O14: LINUX_Auditd_SYSCALL LINUX_PROCESS_EXEC | Q14: 1 | R14: Filter | S14: procName REGEXP "(?i).*(useradd|usermod)$" AND command REGEXP "(?i)\s*(?:-u\s*0|--uid(?:\s+|=)\s*0).*" | T14: hostName,user,procName,command | U14: COUNT(*) >= 1 | V14: 300 | X14: Linux Collector: LINUX_PROCESS_EXEC Linux Collector: LINUX_Auditd_SYSCALL | Z14: Detects execution of useradd or usermod with an option assigning UID 0 to an account. A newly created UID 0 account has root-equivalent privileges, while assigning UID 0 to an existing account can provide persistent privileged access. This rule detects the command attempt and does not necessarily confirm that the account change succeeded. Validate the process exit status and resulting account state in /etc/passwd. Legitimate UID 0 account creation or modification is rare and should be investigated. | AA14: https://filestore.fortinet.com/docs.fortinet.com/fsiem/Public_Resource_Access/7_6_0/rules/PH_RULE_Linux_Root_Equivalent_Account_Command.htm
A15: PH_Rule_Linux_PAM_Configuration_Modified | B15: Linux: PAM Configuration Modified | C15: New ITDR (7.6.0) | D15: Identity-core | E15: Privilege/account change | F15: Enabled | G15: 8 | H15: Medium | I15: Security | J15: Correlation | K15: Streaming | L15: Defense Evasion | M15: T1556.003 | N15: Linux File Monitoring via Linux Collector | O15: FSM_LINUX_FILE_MODIFY | Q15: 1 | R15: Filter | S15: targetOsObjName REGEXP "^/etc/pam\.conf$|^/etc/pam\.d/.*" | T15: hostName,user,targetOsObjName | U15: COUNT(*) >= 1 | V15: 300 | X15: Linux Collector: FSM_LINUX_FILE_MODIFY | Z15: Detects modifications to Linux PAM configuration files under /etc/pam.d/ or to /etc/pam.conf. Adversaries may alter PAM configuration to bypass authentication, capture credentials, execute unauthorized programs during authentication, weaken password controls, or establish persistent access. Legitimate package upgrades, configuration-management systems, and approved authentication-policy changes may also modify these files. Tune approved administrative tools, automation accounts, package managers, and maintenance windows before enabling in production. | AA15: https://filestore.fortinet.com/docs.fortinet.com/fsiem/Public_Resource_Access/7_6_0/rules/PH_RULE_Linux_PAM_Configuration_Modified.htm
A16: PH_Rule_Win_Account_Created_Added_To_Privileged_Group | B16: Windows: Account Created Then Added To Privileged Group | C16: New ITDR (7.6.0) | D16: Identity-core | E16: Active Directory, Windows Security log, Privilege/account change | F16: Enabled | G16: 9 | H16: High | I16: Security | J16: Correlation | K16: Streaming | L16: Persistence | M16: T1136.001, T1136.002, T1098.007 | N16: Microsoft Windows Security Log via OMI or Windows Collector | O16: Win-Security-4720 Win-Security-4728 Win-Security-4732 Win-Security-4756 | Q16: 2 | R16: AccountCreated AND AddedToPrivilegedGroup | S16: [AccountCreated] targetUser IS NOT NULL AND targetUserSID IS NOT NULL [AddedToPrivilegedGroup] targetUser IS NOT NULL AND targetUserSID IS NOT NULL AND groupID REGEXP "(?i)^(?:S-1-5-32-(?:544|548|549|550|551|552|555|556|557|569|573|574|578|580)|S-1-5-21-[0-9]+-[0-9]+-[0-9]+-(?:512|518|519|520|526|527))$" | T16: [AccountCreated] hostName,user,securityId,targetUser,targetUserSID [AddedToPrivilegedGroup] hostName,user,securityId,targetUser,targetUserSID,targetUserGrp,groupID | U16: [AccountCreated] COUNT(*) >= 1 [AddedToPrivilegedGroup] COUNT(*) >= 1 | V16: 1800 | W16: AccountCreated.hostName = AddedToPrivilegedGroup.hostName AND AccountCreated.targetUserSID = AddedToPrivilegedGroup.targetUserSID | X16: Windows Security log: Security 4720 Windows Security log: Security 4728 Windows Security log: Security 4732 Windows Security log: Security 4756 | Y16: a4 | Z16: Detects a newly created local or domain user account that is subsequently added to a commonly privileged Windows or Active Directory security group. Monitored groups include Administrators, Domain Admins, Enterprise Admins, Schema Admins, Group Policy Creator Owners, Key Admins, Enterprise Key Admins, Account Operators, Server Operators, Print Operators, Backup Operators, Replicator, Remote Desktop Users, Network Configuration Operators, Incoming Forest Trust Builders, Cryptographic Operators, Event Log Readers, Certificate Service DCOM Access, Hyper-V Administrators, and Remote Management Users. Adversaries may create an account and grant it elevated, administrative, remote-access, or security-sensitive group membership to establish persistence or gain privileged access. Legitimate provisioning workflows may also trigger this rule; tune approved identity-management systems, service accounts, automation accounts, administrative tools, and change windows before enabling in production. | AA16: https://filestore.fortinet.com/docs.fortinet.com/fsiem/Public_Resource_Access/7_6_0/rules/PH_RULE_Win_Account_Created_Added_To_Privileged_Group.htm
A17: PH_Rule_Win_ADCS_ESC10_Certificate_Mapping_Config_Command | B17: Windows: AD CS ESC10 Certificate Mapping Configuration Changed via Command | C17: New ITDR (7.6.0) | D17: Identity-core | E17: Active Directory, Windows Security log, AD CS | F17: Enabled | G17: 8 | H17: Medium | I17: Security | J17: Correlation | K17: Streaming | L17: Defense Evasion | M17: T1553.004 | N17: Microsoft Windows Powershell Operational Logs via Windows Collector Microsoft Windows Security Log via OMI or Windows Collector Microsoft Windows Sysmon via Windows Collector | O17: Win-PowerShell-4104 Win-Security-4688 Win-Sysmon-1-Create-Process | Q17: 1 | R17: Filter | S17: command REGEXP "(?i).*(?:reg(?:\.exe)?\s+(?:add|delete)|Set-ItemProperty|New-ItemProperty|Remove-ItemProperty).*?(?:StrongCertificateBindingEnforcement|CertificateMappingMethods).*" | T17: hostName,user,procName,command | U17: COUNT(*) >= 1 | V17: 300 | X17: Windows Security log: Security 4688 Sysmon: Sysmon 1 PowerShell Operational: PowerShell 4104 | Y17: s1, s4 | Z17: Detects command-line or PowerShell activity that modifies Windows certificate mapping configuration associated with ESC10, including StrongCertificateBindingEnforcement or CertificateMappingMethods. Weakening these settings may permit certificates to authenticate through weak account mappings. The resulting registry value must be reviewed to determine whether security was weakened. | AA17: https://filestore.fortinet.com/docs.fortinet.com/fsiem/Public_Resource_Access/7_6_0/rules/PH_RULE_Win_ADCS_ESC10_Certificate_Mapping_Config_Command.htm
A18: PH_Rule_Win_ADCS_ESC13_OID_Group_Link_Modified | B18: Windows: AD CS ESC13 OID Group Link Modified | C18: New ITDR (7.6.0) | D18: Identity-core | E18: Active Directory, Windows Security log, AD CS, Credential Access | F18: Enabled | G18: 8 | H18: Medium | I18: Security | J18: Correlation | K18: Streaming | L18: Credential Access | M18: T1606.002 | N18: Microsoft Windows Security Log via OMI or Windows Collector | O18: Win-Security-5136 | Q18: 1 | R18: Filter | S18: propName="msDS-OIDToGroupLink" | T18: hostName,user,osObjName,osObjType,propName,propValue | U18: COUNT(*) >= 1 | V18: 300 | X18: Windows Security log: Security 5136 | Y18: a6 | Z18: Detects modification of the msDS-OIDToGroupLink attribute on an Active Directory issuance-policy OID object. This link can associate a certificate issuance policy with an Active Directory group and may enable ESC13-style privilege escalation when an attacker can enroll for a certificate containing the linked issuance policy. | AA18: https://filestore.fortinet.com/docs.fortinet.com/fsiem/Public_Resource_Access/7_6_0/rules/PH_RULE_Win_ADCS_ESC13_OID_Group_Link_Modified.htm
A19: PH_Rule_Win_ADCS_ESC14_Explicit_Certificate_Mapping_Modified | B19: Windows: AD CS ESC14 Explicit Certificate Mapping Modified | C19: New ITDR (7.6.0) | D19: Identity-core | E19: Active Directory, Windows Security log, AD CS, Credential Access | F19: Enabled | G19: 8 | H19: Medium | I19: Security | J19: Correlation | K19: Streaming | L19: Credential Access | M19: T1606.002 | N19: Microsoft Windows Security Log via OMI or Windows Collector | O19: Win-Security-5136 | Q19: 1 | R19: Filter | S19: propName="altSecurityIdentities" | T19: hostName,user,osObjName,osObjType,propName,propValue | U19: COUNT(*) >= 1 | V19: 300 | X19: Windows Security log: Security 5136 | Y19: a6 | Z19: Detects modification of the altSecurityIdentities attribute on an Active Directory account. This attribute defines explicit certificate-to-account mappings and may be abused in ESC14 to map an attacker-controlled certificate to another user or computer. Legitimate certificate mapping administration may also trigger this rule. | AA19: https://filestore.fortinet.com/docs.fortinet.com/fsiem/Public_Resource_Access/7_6_0/rules/PH_RULE_Win_ADCS_ESC14_Explicit_Certificate_Mapping_Modified.htm
A20: PH_Rule_Win_ADCS_ESC16_SID_Extension_Disabled_Command | B20: Windows: AD CS ESC16 SID Security Extension Disabled via Command | C20: New ITDR (7.6.0) | D20: Identity-core | E20: Active Directory, Windows Security log, AD CS | F20: Enabled | G20: 9 | H20: High | I20: Security | J20: Correlation | K20: Streaming | L20: Defense Evasion | M20: T1553.004 | N20: Microsoft Windows Powershell Operational Logs via Windows Collector Microsoft Windows Security Log via OMI or Windows Collector Microsoft Windows Sysmon via Windows Collector | O20: Win-PowerShell-4104 Win-Security-4688 Win-Sysmon-1-Create-Process | Q20: 1 | R20: Filter | S20: command REGEXP "(?i).*(?:certutil(?:\.exe)?.*-setreg.*DisableExtensionList|Set-ItemProperty.*DisableExtensionList).*1\.3\.6\.1\.4\.1\.311\.25\.2.*" | T20: hostName,user,procName,command | U20: COUNT(*) >= 1 | V20: 300 | X20: Windows Security log: Security 4688 Sysmon: Sysmon 1 PowerShell Operational: PowerShell 4104 | Y20: s1, s4 | Z20: Detects certutil or PowerShell command activity that adds the szOID_NTDS_CA_SECURITY_EXT OID to the certification authority DisableExtensionList. Disabling this extension prevents newly issued certificates from containing the Active Directory SID security extension and may enable ESC16-style certificate mapping abuse. | AA20: https://filestore.fortinet.com/docs.fortinet.com/fsiem/Public_Resource_Access/7_6_0/rules/PH_RULE_Win_ADCS_ESC16_SID_Extension_Disabled_Command.htm
A21: PH_Rule_Win_ADCS_ESC2_Any_Purpose_EKU_Added | B21: Windows: AD CS ESC2 Any Purpose EKU Added to Certificate Template | C21: New ITDR (7.6.0) | D21: Identity-core | E21: Active Directory, Windows Security log, AD CS, Credential Access | F21: Enabled | G21: 7 | H21: Medium | I21: Security | J21: Correlation | K21: Streaming | L21: Credential Access | M21: T1606.002 | N21: Microsoft Windows Security Log via OMI or Windows Collector | O21: Win-Security-5136 | Q21: 1 | R21: Filter | S21: osObjType="pKICertificateTemplate" AND propName="pKIExtendedKeyUsage" AND propValue REGEXP "(?i).*(?:Any Purpose|2\.5\.29\.37\.0).*" | T21: hostName,user,osObjName,propName,propValue | U21: COUNT(*) >= 1 | V21: 300 | X21: Windows Security log: Security 5136 | Y21: a6 | Z21: Detects modification of an AD CS certificate template to include the Any Purpose extended key usage OID. This configuration is associated with ESC2 because certificates issued from the template may be usable for authentication or other unintended purposes. Additional review of enrollment permissions and template settings is required to confirm exploitability. | AA21: https://filestore.fortinet.com/docs.fortinet.com/fsiem/Public_Resource_Access/7_6_0/rules/PH_RULE_Win_ADCS_ESC2_Any_Purpose_EKU_Added.htm
A22: PH_Rule_Win_ADCS_ESC3_Enrollment_Agent_EKU_Added | B22: Windows: AD CS ESC3 Enrollment Agent EKU Added to Certificate Template | C22: New ITDR (7.6.0) | D22: Identity-core | E22: Active Directory, Windows Security log, AD CS, Credential Access | F22: Enabled | G22: 8 | H22: Medium | I22: Security | J22: Correlation | K22: Streaming | L22: Credential Access | M22: T1606.002 | N22: Microsoft Windows Security Log via OMI or Windows Collector | O22: Win-Security-5136 | Q22: 1 | R22: Filter | S22: osObjType="pKICertificateTemplate" AND propName="pKIExtendedKeyUsage" AND propValue REGEXP "(?i).*(?:Certificate Request Agent|1\.3\.6\.1\.4\.1\.311\.20\.2\.1).*" | T22: hostName,user,osObjName,propName,propValue | U22: COUNT(*) >= 1 | V22: 300 | X22: Windows Security log: Security 5136 | Y22: a6 | Z22: Detects modification of an AD CS certificate template to include the Certificate Request Agent extended key usage. This EKU permits an issued certificate to sign certificate requests on behalf of other users and is associated with ESC3. Additional review of enrollment-agent restrictions, issuance requirements, and enrollment permissions is required to confirm exploitability. | AA22: https://filestore.fortinet.com/docs.fortinet.com/fsiem/Public_Resource_Access/7_6_0/rules/PH_RULE_Win_ADCS_ESC3_Enrollment_Agent_EKU_Added.htm
A23: PH_Rule_Win_ADCS_ESC5_PKI_Object_ACL_Modified | B23: Windows: AD CS ESC5 PKI Object ACL Modified | C23: New ITDR (7.6.0) | D23: Identity-core | E23: Active Directory, Windows Security log, AD CS, Credential Access | F23: Enabled | G23: 8 | H23: Medium | I23: Security | J23: Correlation | K23: Streaming | L23: Credential Access | M23: T1606.002 | N23: Microsoft Windows Security Log via OMI or Windows Collector | O23: Win-Security-5136 | Q23: 1 | R23: Filter | S23: propName="nTSecurityDescriptor" AND osObjName REGEXP "(?i).*(?:CN=Public Key Services|CN=Enrollment Services|CN=Certificate Templates|CN=Certification Authorities|CN=AIA|CN=CDP).*" | T23: hostName,user,osObjName,osObjType,propName | U23: COUNT(*) >= 1 | V23: 300 | X23: Windows Security log: Security 5136 | Y23: a6 | Z23: Detects modification of the security descriptor on an Active Directory PKI object beneath the Public Key Services configuration container. Unauthorized control of PKI objects may enable ESC5-style abuse, including modification of certificate templates, certification authorities, enrollment services, or other certificate infrastructure configuration. | AA23: https://filestore.fortinet.com/docs.fortinet.com/fsiem/Public_Resource_Access/7_6_0/rules/PH_RULE_Win_ADCS_ESC5_PKI_Object_ACL_Modified.htm
A24: PH_Rule_Win_ADCS_ESC7_CA_Security_Permissions_Changed | B24: Windows: AD CS ESC7 CA Security Permissions Changed | C24: New ITDR (7.6.0) | D24: Identity-core | E24: Active Directory, Windows Security log, AD CS, Credential Access | F24: Enabled | G24: 8 | H24: Medium | I24: Security | J24: Correlation | K24: Streaming | L24: Credential Access | M24: T1606.002 | N24: Microsoft Windows Security Log via OMI or Windows Collector | O24: Win-Security-4882 | Q24: 1 | R24: Filter | S24: — | T24: hostName,user | U24: COUNT(*) >= 1 | V24: 300 | X24: Windows Security log: Security 4882 | Y24: ca | Z24: Detects a change to Certification Authority security permissions. Such changes may grant or alter CA administration rights such as Manage CA or Manage Certificates and may enable ESC7-style privilege escalation. Legitimate PKI administration may also generate this event, and the resulting access control changes should be reviewed. | AA24: https://filestore.fortinet.com/docs.fortinet.com/fsiem/Public_Resource_Access/7_6_0/rules/PH_RULE_Win_ADCS_ESC7_CA_Security_Permissions_Changed.htm
A25: PH_Rule_Win_ADCS_Web_Enrollment_Certificate_Request | B25: Windows: AD CS Web Enrollment Certificate Request | C25: New ITDR (7.6.0) | D25: Identity-core | E25: Active Directory, AD CS, Credential Access | F25: Enabled | G25: 7 | H25: Medium | I25: Security | J25: Correlation | K25: Streaming | L25: Credential Access | M25: T1606.002 | N25: Microsoft IIS via Windows Collector | O25: IIS-Web-Bad-Request IIS-Web-Client-Access-Denied IIS-Web-Client-Error IIS-Web-Forbidden-Access-Denied IIS-Web-Request-Redirect IIS-Web-Request-Success IIS-Web-Server-Error | Q25: 1 | R25: Filter | S25: httpMethod IN ("POST","post") AND uriStem REGEXP "(?i)^.*/certsrv/(?:certfnsh\.asp|certnew\.cer)$" | T25: reptDevName,srcIpAddr,user,httpMethod,uriStem | U25: COUNT(*) >= 1 | V25: 300 | X25: IIS log: IIS web request | Z25: Detects access to Active Directory Certificate Services Web Enrollment certificate-request submission endpoints. Web enrollment may be used legitimately, but unexpected requests from servers, network appliances, unmanaged systems, or other unusual sources should be investigated for possible NTLM relay or unauthorized certificate enrollment. | AA25: https://filestore.fortinet.com/docs.fortinet.com/fsiem/Public_Resource_Access/7_6_0/rules/PH_RULE_Win_ADCS_Web_Enrollment_Certificate_Request.htm
A26: PH_Rule_Win_AdminSDHolder_Modified | B26: Windows: AdminSDHolder Modified | C26: New ITDR (7.6.0) | D26: Identity-core | E26: Active Directory, Windows Security log, Privilege/account change | F26: Enabled | G26: 9 | H26: High | I26: Security | J26: Correlation | K26: Streaming | L26: Persistence | M26: T1098.001 | N26: Microsoft Windows Security Log via OMI or Windows Collector | O26: Win-Security-5136 | Q26: 1 | R26: Filter | S26: osObjName REGEXP ".*AdminSDHolder.*" | T26: hostName,user,osObjName,propName,propValue | U26: COUNT(*) >= 1 | V26: 300 | X26: Windows Security log: Security 5136 | Y26: a6 | Z26: Detects changes to the AdminSDHolder object in Active Directory. The AdminSDHolder object is a template for permissions on protected accounts (Domain Admins, Enterprise Admins, etc). An adversary may modify AdminSDHolder to establish persistence by granting privileges to non-privileged accounts. | AA26: https://filestore.fortinet.com/docs.fortinet.com/fsiem/Public_Resource_Access/7_6_0/rules/PH_RULE_Win_AdminSDHolder_Modified.htm
A27: PH_Rule_Win_Auth_Package_Modified | B27: Windows: Authentication Package Modified | C27: New ITDR (7.6.0) | D27: Identity-core | E27: Windows Security log | F27: Enabled | G27: 9 | H27: High | I27: Security | J27: Correlation | K27: Streaming | L27: Persistence | M27: T1547.002 | N27: Microsoft Windows Powershell Operational Logs via Windows Collector Microsoft Windows Security Log via OMI or Windows Collector Microsoft Windows Sysmon via Windows Collector | O27: Win-PowerShell-4104 Win-Security-4688 Win-Sysmon-1-Create-Process | Q27: 1 | R27: Filter | S27: command REGEXP ".*(?:Security Packages|Authentication Packages).*" | T27: hostName,user,procName,command | U27: COUNT(*) >= 1 | V27: 300 | X27: Windows Security log: Security 4688 Sysmon: Sysmon 1 PowerShell Operational: PowerShell 4104 | Y27: s1, s4 | Z27: Detects command lines or script blocks that modify LSASS authentication packages by writing to the Security Packages or Authentication Packages registry values. An adversary may register a malicious authentication package to load code into LSASS at boot, enabling credential theft and persistence. | AA27: https://filestore.fortinet.com/docs.fortinet.com/fsiem/Public_Resource_Access/7_6_0/rules/PH_RULE_Win_Auth_Package_Modified.htm
A28: PH_Rule_Win_BloodHound_SharpHound_Execution | B28: Windows: BloodHound or SharpHound Execution | C28: New ITDR (7.6.0) | D28: Identity-core | E28: Active Directory, Windows Security log | F28: Enabled | G28: 9 | H28: High | I28: Security | J28: Correlation | K28: Streaming | L28: Discovery | M28: T1087.002 | N28: Microsoft Windows Powershell Operational Logs via Windows Collector Microsoft Windows Security Log via OMI or Windows Collector Microsoft Windows Sysmon via Windows Collector | O28: Win-PowerShell-4104 Win-Security-4688 Win-Sysmon-1-Create-Process | Q28: 1 | R28: Filter | S28: (procName REGEXP "(?i).*(?:SharpHound|BloodHound)(?:\.exe|\.ps1)?$" OR command REGEXP "(?i).*(?:SharpHound|BloodHound|Invoke-BloodHound|--?CollectionMethods?).*") | T28: hostName,user,procName,command | U28: COUNT(*) >= 1 | V28: 300 | X28: Windows Security log: Security 4688 Sysmon: Sysmon 1 PowerShell Operational: PowerShell 4104 | Y28: s1, s4 | Z28: Detects process names, command lines, or PowerShell script content containing explicit BloodHound or SharpHound collection-tool indicators. These tools collect Active Directory relationship, account, group, session, permission, and trust information for attack-path analysis. Authorized penetration testing and identity-security assessment activity may also trigger this rule. | AA28: https://filestore.fortinet.com/docs.fortinet.com/fsiem/Public_Resource_Access/7_6_0/rules/PH_RULE_Win_BloodHound_SharpHound_Execution.htm
A29: PH_Rule_Win_CA_Configuration_Changed | B29: Windows: CA Configuration Changed | C29: New ITDR (7.6.0) | D29: Identity-core | E29: Active Directory, Windows Security log, AD CS | F29: Enabled | G29: 9 | H29: High | I29: Security | J29: Correlation | K29: Streaming | L29: Resource Development | M29: T1587.003 | N29: Microsoft Windows Security Log via OMI or Windows Collector | O29: Win-Security-4890 Win-Security-4891 Win-Security-4892 Win-Security-4893 Win-Security-4894 | Q29: 1 | R29: Filter | S29: — | T29: hostName,user | U29: COUNT(*) >= 1 | V29: 300 | X29: Windows Security log: Security 4890 Windows Security log: Security 4891 Windows Security log: Security 4892 Windows Security log: Security 4893 Windows Security log: Security 4894 | Y29: ca | Z29: Detects changes to Active Directory Certificate Services certificate authority configuration, including certificate manager settings, configuration entries, CA properties, and key archival or import operations. Such changes may indicate PKI tampering, unauthorized CA reconfiguration, or preparation for certificate-based privilege escalation. Legitimate PKI administration, scheduled CA maintenance, and approved change-window activity may also generate these events. | AA29: https://filestore.fortinet.com/docs.fortinet.com/fsiem/Public_Resource_Access/7_6_0/rules/PH_RULE_Win_CA_Configuration_Changed.htm
A30: PH_Rule_Win_Certificate_Template_Modified | B30: Windows: Certificate Template Modified | C30: New ITDR (7.6.0) | D30: Identity-core | E30: Active Directory, Windows Security log, AD CS, Credential Access | F30: Enabled | G30: 8 | H30: Medium | I30: Security | J30: Correlation | K30: Streaming | L30: Credential Access | M30: T1606.002 | N30: Microsoft Windows Security Log via OMI or Windows Collector | O30: Win-Security-5136 | Q30: 1 | R30: Filter | S30: osObjType = "pKICertificateTemplate" | T30: hostName,user,osObjName,propName | U30: COUNT(*) >= 1 | V30: 300 | X30: Windows Security log: Security 5136 | Y30: a6 | Z30: Detects modification of an Active Directory Certificate Services certificate template. Certificate template changes can alter enrollment permissions, authentication capabilities, subject-name handling, issuance requirements, or other security-sensitive properties. Legitimate PKI administration may also trigger this rule. | AA30: https://filestore.fortinet.com/docs.fortinet.com/fsiem/Public_Resource_Access/7_6_0/rules/PH_RULE_Win_Certificate_Template_Modified.htm
A31: PH_Rule_Win_Certipy_Credential_Abuse | B31: Windows: Certipy Credential Abuse | C31: New ITDR (7.6.0) | D31: Identity-core | E31: Active Directory, Windows Security log, AD CS, Credential Access | F31: Enabled | G31: 9 | H31: High | I31: Security | J31: Correlation | K31: Streaming | L31: Credential Access | M31: T1606.002 | N31: Microsoft Windows Powershell Operational Logs via Windows Collector Microsoft Windows Security Log via OMI or Windows Collector Microsoft Windows Sysmon via Windows Collector | O31: Win-PowerShell-4104 Win-Security-4688 Win-Sysmon-1-Create-Process | Q31: 1 | R31: Filter | S31: command REGEXP ".*certipy.*" | T31: hostName,user,procName,command | U31: COUNT(*) >= 1 | V31: 300 | X31: Windows Security log: Security 4688 Sysmon: Sysmon 1 PowerShell Operational: PowerShell 4104 | Y31: s1, s4 | Z31: Detects command lines or process names associated with Certipy credential abuse. Certipy is a Python tool for enumerating and abusing Active Directory Certificate Services (AD CS), enabling attacks such as certificate template exploitation, ESC1-ESC8 abuse, and forged certificate-based authentication to escalate privileges and impersonate users. | AA31: https://filestore.fortinet.com/docs.fortinet.com/fsiem/Public_Resource_Access/7_6_0/rules/PH_RULE_Win_Certipy_Credential_Abuse.htm
A32: PH_Rule_Win_Comsvcs_MiniDump_LSASS | B32: Windows: comsvcs.dll MiniDump LSASS | C32: New ITDR (7.6.0) | D32: Identity-core | E32: Windows Security log, Credential Access | F32: Enabled | G32: 9 | H32: High | I32: Security | J32: Correlation | K32: Streaming | L32: Credential Access | M32: T1003.001 | N32: Microsoft Windows Security Log via OMI or Windows Collector Microsoft Windows Sysmon via Windows Collector | O32: Win-Security-4688 Win-Sysmon-1-Create-Process | Q32: 1 | R32: Filter | S32: procName REGEXP ".*rundll32.exe$" AND command REGEXP ".*comsvcs.dll.*MiniDump.*lsass.*" | T32: hostName,user,procName,command | U32: COUNT(*) >= 1 | V32: 300 | X32: Windows Security log: Security 4688 Sysmon: Sysmon 1 | Y32: s1 | Z32: Detects rundll32 loading comsvcs.dll to invoke MiniDump against LSASS. This technique abuses the built-in Windows comsvcs.dll MiniDump export to dump LSASS process memory without dropping procdump, evading simple tool-name-based detections and enabling credential theft. | AA32: https://filestore.fortinet.com/docs.fortinet.com/fsiem/Public_Resource_Access/7_6_0/rules/PH_RULE_Win_Comsvcs_MiniDump_LSASS.htm
A33: PH_Rule_Win_Domain_Trust_Modified | B33: Windows: Domain Trust Modified | C33: New ITDR (7.6.0) | D33: Identity-core | E33: Active Directory, Windows Security log | F33: Enabled | G33: 9 | H33: High | I33: Security | J33: Correlation | K33: Streaming | L33: Discovery | M33: T1482 | N33: Microsoft Windows Security Log via OMI or Windows Collector | O33: Win-Security-4706 Win-Security-4707 Win-Security-4716 Win-Security-5136 | Q33: 1 | R33: Filter | S33: ((osObjType REGEXP ".*trustedDomain.*")) | T33: hostName,user,osObjName,osObjType | U33: COUNT(*) >= 1 | V33: 300 | X33: Windows Security log: Security 4706 Windows Security log: Security 4707 Windows Security log: Security 4716 Windows Security log: Security 5136 | Y33: a6 | Z33: Detects domain trust object creation or modification. An adversary may create or modify domain trusts to enable lateral movement across domains or facilitate credential theft and discovery. | AA33: https://filestore.fortinet.com/docs.fortinet.com/fsiem/Public_Resource_Access/7_6_0/rules/PH_RULE_Win_Domain_Trust_Modified.htm
A34: PH_Rule_Win_ESC1_Relevant_Template_Attribute_Modified | B34: Windows: ESC1-Relevant Certificate Template Attribute Modified | C34: New ITDR (7.6.0) | D34: Identity-core | E34: Active Directory, Windows Security log, AD CS, Credential Access | F34: Enabled | G34: 9 | H34: High | I34: Security | J34: Correlation | K34: Streaming | L34: Credential Access | M34: T1606.002 | N34: Microsoft Windows Security Log via OMI or Windows Collector | O34: Win-Security-5136 | Q34: 1 | R34: Filter | S34: osObjType = "pKICertificateTemplate" AND propName REGEXP "(?i)^(?:msPKI-Certificate-Name-Flag|pKIExtendedKeyUsage)$" | T34: hostName,user,osObjName,propName,propValue | U34: COUNT(*) >= 1 | V34: 300 | X34: Windows Security log: Security 5136 | Y34: a6 | Z34: Detects modification of certificate template attributes associated with ESC1 exposure, including subject-name handling and extended key usage. This event does not by itself prove that the template is exploitable; the resulting template configuration, enrollment permissions, issuance requirements, and authentication-capable EKUs should be reviewed. | AA34: https://filestore.fortinet.com/docs.fortinet.com/fsiem/Public_Resource_Access/7_6_0/rules/PH_RULE_Win_ESC1_Relevant_Template_Attribute_Modified.htm
A35: PH_Rule_Win_ESC4_Certificate_Template_ACL_Modified | B35: Windows: ESC4 Certificate Template ACL Modified | C35: New ITDR (7.6.0) | D35: Identity-core | E35: Active Directory, Windows Security log, AD CS, Credential Access | F35: Enabled | G35: 9 | H35: High | I35: Security | J35: Correlation | K35: Streaming | L35: Credential Access | M35: T1606.002 | N35: Microsoft Windows Security Log via OMI or Windows Collector | O35: Win-Security-5136 | Q35: 1 | R35: Filter | S35: osObjType = "pKICertificateTemplate" AND propName REGEXP "(?i)^nTSecurityDescriptor$" | T35: hostName,user,osObjName,propName | U35: COUNT(*) >= 1 | V35: 300 | X35: Windows Security log: Security 5136 | Y35: a6 | Z35: Detects modification of the security descriptor on an Active Directory Certificate Services certificate template. An unauthorized principal with template write permissions may alter security-sensitive template settings or enrollment permissions, creating an ESC4 abuse path. Review the resulting access control entries and the account that performed the change. | AA35: https://filestore.fortinet.com/docs.fortinet.com/fsiem/Public_Resource_Access/7_6_0/rules/PH_RULE_Win_ESC4_Certificate_Template_ACL_Modified.htm
A36: PH_Rule_Win_ESC6_EDITF_ATTRIBUTESUBJECTALTNAME2_Enabled | B36: Windows: ESC6 EDITF-ATTRIBUTESUBJECTALTNAME2 Enabled with Certutil | C36: New ITDR (7.6.0) | D36: Identity-core | E36: Windows Security log, AD CS, Credential Access | F36: Enabled | G36: 10 | H36: High | I36: Security | J36: Correlation | K36: Streaming | L36: Credential Access | M36: T1606.002 | N36: Microsoft Windows Powershell Operational Logs via Windows Collector Microsoft Windows Security Log via OMI or Windows Collector Microsoft Windows Sysmon via Windows Collector | O36: Win-PowerShell-4104 Win-Security-4688 Win-Sysmon-1-Create-Process | Q36: 1 | R36: Filter | S36: command REGEXP "(?i).*certutil(?:\.exe)?.*-setreg.*policy\\EditFlags.*\+EDITF_ATTRIBUTESUBJECTALTNAME2.*" | T36: hostName,user,procName,command | U36: COUNT(*) >= 1 | V36: 300 | X36: Windows Security log: Security 4688 Sysmon: Sysmon 1 PowerShell Operational: PowerShell 4104 | Y36: s1, s4 | Z36: Detects a certutil command that enables the EDITF_ATTRIBUTESUBJECTALTNAME2 certification authority policy flag. This setting permits certificate requesters to provide subject alternative names and can create an ESC6 abuse path when authentication-capable certificate templates are available. Emergency or approved PKI configuration changes may also trigger this rule. | AA36: https://filestore.fortinet.com/docs.fortinet.com/fsiem/Public_Resource_Access/7_6_0/rules/PH_RULE_Win_ESC6_EDITF_ATTRIBUTESUBJECTALTNAME2_Enabled.htm
A37: PH_Rule_Win_Kerberoasting_Multiple_SPNs | B37: Windows: Kerberoasting Multiple SPNs | C37: New ITDR (7.6.0) | D37: Identity-core | E37: Active Directory, Windows Security log, Kerberos, Credential Access | F37: Enabled | G37: 7 | H37: Medium | I37: Security | J37: Correlation | K37: Streaming | L37: Credential Access | M37: T1558.003 | N37: Microsoft Windows Security Log via OMI or Windows Collector | O37: Win-Security-4769-success | Q37: 1 | R37: Filter | S37: serviceName IS NOT NULL AND serviceName != "krbtgt" | T37: user,srcIpAddr | U37: COUNT(DISTINCT serviceName) >= 10 | V37: 600 | X37: Windows Security log: Security 4769 | Y37: a2 | Z37: Detects a single account requesting successful Kerberos service tickets for many distinct service names within a short period. This behavior may indicate Kerberoasting, in which an adversary obtains service-ticket material for offline password cracking, but it may also result from legitimate automated or service-discovery activity. Events are aggregated by user and source IP rather than domain controller hostname so that a single burst distributed across multiple domain controllers is not split into separate groups. | AA37: https://filestore.fortinet.com/docs.fortinet.com/fsiem/Public_Resource_Access/7_6_0/rules/PH_RULE_Win_Kerberoasting_Multiple_SPNs.htm
... A46: PH_Rule_Win_Procdump_LSASS_Dump | B46: Windows: Procdump LSASS Dump | C46: New ITDR (7.6.0) | D46: Identity-core | E46: Windows Security log, Kerberos, Credential Access | F46: Enabled | G46: 9 | H46: High | I46: Security | J46: Correlation | K46: Streaming | L46: Credential Access | M46: T1003.001 | N46: Microsoft Windows Security Log via OMI or Windows Collector Microsoft Windows Sysmon via Windows Collector | O46: Win-Security-4688 Win-Sysmon-1-Create-Process | Q46: 1 | R46: Filter | S46: procName REGEXP ".*procdump.*" AND command REGEXP ".*lsass.*" | T46: hostName,user,procName,command | U46: COUNT(*) >= 1 | V46: 300 | X46: Windows Security log: Security 4688 Sysmon: Sysmon 1 | Y46: s1 | Z46: Detects ProcDump targeting the LSASS process. ProcDump (Sysinternals) is commonly abused by adversaries to create a minidump of LSASS memory, enabling extraction of credentials, NTLM hashes, and Kerberos tickets for credential theft and lateral movement. | AA46: https://filestore.fortinet.com/docs.fortinet.com/fsiem/Public_Resource_Access/7_6_0/rules/PH_RULE_Win_Procdump_LSASS_Dump.htm
A47: PH_Rule_Win_PsExec_Service_Creation | B47: Windows: PsExec Service Creation | C47: New ITDR (7.6.0) | D47: Identity-core | F47: Enabled | G47: 9 | H47: High | I47: Security | J47: Correlation | K47: Streaming | L47: Execution | M47: T1569.002 | N47: Microsoft Windows System Log via OMI or Windows Collector | O47: Win-System-Service-Control-Manager-7045 | Q47: 1 | R47: Filter | S47: (serviceName REGEXP "(?i)^(?:PSEXESVC|PAExec.*|RemComSvc.*)$" OR serviceFileName REGEXP "(?i).*[\\/](?:PSEXESVC|PAExec[^\\/]*|RemComSvc[^\\/]*)\.exe(?:\s.*)?$") | T47: hostName,user,serviceName,serviceFileName | U47: COUNT(*) >= 1 | V47: 300 | X47: Windows System log: System 7045 | Z47: Detects PsExec-style service installation. Adversaries use PsExec and similar tools (PAExec, RemCom) to execute commands remotely by installing and starting a temporary service, enabling lateral movement across hosts. | AA47: https://filestore.fortinet.com/docs.fortinet.com/fsiem/Public_Resource_Access/7_6_0/rules/PH_RULE_Win_PsExec_Service_Creation.htm
A48: PH_Rule_Win_Pypykatz_Credential_Dumping | B48: Windows: Pypykatz Credential Dumping via Process or PowerShell | C48: New ITDR (7.6.0) | D48: Identity-core | E48: Windows Security log, Credential Access | F48: Enabled | G48: 9 | H48: High | I48: Security | J48: Correlation | K48: Streaming | L48: Credential Access | M48: T1003.001 | N48: Microsoft Windows Powershell Operational Logs via Windows Collector Microsoft Windows Security Log via OMI or Windows Collector Microsoft Windows Sysmon via Windows Collector | O48: Win-PowerShell-4104 Win-Security-4688 Win-Sysmon-1-Create-Process | Q48: 1 | R48: Filter | S48: (command REGEXP ".*pypykatz.*" OR procName REGEXP ".*pypykatz.*") | T48: hostName,user,procName,command | U48: COUNT(*) >= 1 | V48: 300 | X48: Windows Security log: Security 4688 Sysmon: Sysmon 1 PowerShell Operational: PowerShell 4104 | Y48: s1, s4 | Z48: Detects command lines or process names associated with Pypykatz credential dumping. Pypykatz is a Python implementation of Mimikatz that extracts credentials from LSASS memory and other credential stores. | AA48: https://filestore.fortinet.com/docs.fortinet.com/fsiem/Public_Resource_Access/7_6_0/rules/PH_RULE_Win_Pypykatz_Credential_Dumping.htm
...

Sheet Subpatterns
A1: Rule ID | B1: Rule name | C1: ITDR status | D1: Subpattern | E1: Event types | F1: Excluded event types | G1: Filters (non-eventType) | H1: Group-by | I1: Aggregate | J1: Full subpattern query | K1: Trigger expression | L1: Time window (s)
A2: PH_Rule_Azure_Entra_ID_Conditional_Access_Disabled | B2: Azure Entra ID: Conditional Access Disabled | C2: New ITDR (7.6.0) | D2: Filter | E2: MS-Entra-AuditLogs-Policy-Update_policy-success | G2: opName REGEXP ".*(?:Delete conditional access policy|Update conditional access policy).*" | H2: user,opName | I2: COUNT(*) >= 1 | J2: eventType = "MS-Entra-AuditLogs-Policy-Update_policy-success" AND opName REGEXP ".*(?:Delete conditional access policy|Update conditional access policy).*" | K2: Filter | L2: 300
A3: PH_Rule_Azure_Entra_ID_Domain_Authentication_Changed | B3: Azure Entra ID: Domain Authentication Changed | C3: New ITDR (7.6.0) | D3: Filter | E3: MS-Entra-AuditLogs-DirectoryMgmt-Set_domain_authentication-success | H3: user,opName,targetDomain | I3: COUNT(*) >= 1 | J3: eventType = "MS-Entra-AuditLogs-DirectoryMgmt-Set_domain_authentication-success" | K3: Filter | L3: 300
A4: PH_Rule_Azure_Entra_ID_External_User_Added_To_Privileged_Group | B4: Azure Entra ID: External User Added To Privileged Group | C4: New ITDR (7.6.0) | D4: Filter | E4: MS-Entra-AuditLogs-GroupMgmt-Add_member_to_group-success | G4: targetUser CONTAIN "#EXT#" AND groupName CONTAIN "Admin" | H4: user,targetUser,opName,groupName | I4: COUNT(*) >= 1 | J4: eventType = "MS-Entra-AuditLogs-GroupMgmt-Add_member_to_group-success" AND targetUser CONTAIN "#EXT#" AND groupName CONTAIN "Admin" | K4: Filter | L4: 300
A5: PH_Rule_Azure_Entra_ID_MFA_Bypass | B5: Azure Entra ID: MFA Bypass Or Satisfied By Claim | C5: New ITDR (7.6.0) | D5: Filter | E5: MS-Entra-SignInLogs-Logon-success | G5: statusDetailedReason REGEXP ".*(?:bypassed|satisfied by claim|not required).*" | H5: user,srcIpAddr,appName,policyStatus | I5: COUNT(*) >= 1 | J5: eventType = "MS-Entra-SignInLogs-Logon-success" AND statusDetailedReason REGEXP ".*(?:bypassed|satisfied by claim|not required).*" | K5: Filter | L5: 300
A6: PH_Rule_Azure_Entra_ID_New_Federation_Domain_Added | B6: Azure Entra ID: New Federation Domain Added | C6: New ITDR (7.6.0) | D6: Filter | E6: MS-Entra-AuditLogs-DirectoryMgmt-Set_federation_settings_on_domain-success | H6: user,opName,targetDomain | I6: COUNT(*) >= 1 | J6: eventType = "MS-Entra-AuditLogs-DirectoryMgmt-Set_federation_settings_on_domain-success" | K6: Filter | L6: 300
A7: PH_Rule_Azure_Entra_ID_OAuth_Secret_Added | B7: Azure Entra ID: OAuth Secret Added | C7: New ITDR (7.6.0) | D7: Filter | E7: MS-Entra-AuditLogs-ApplicationMgmt-Add_service_principal_credentials-success MS-Entra-AuditLogs-ApplicationMgmt-Update_application_Certificates_and_secrets_Mgmt-success | H7: user,targetUser,opName | I7: COUNT(*) >= 1 | J7: eventType IN ("MS-Entra-AuditLogs-ApplicationMgmt-Add_service_principal_credentials-success","MS-Entra-AuditLogs-ApplicationMgmt-Update_application_Certificates_and_secrets_Mgmt-success") | K7: Filter | L7: 300
A8: PH_Rule_Azure_Entra_ID_User_Added_To_Application_Admin | B8: Azure Entra ID: User Added To Application Admin | C8: New ITDR (7.6.0) | D8: Filter | E8: MS-Entra-AuditLogs-RoleMgmt-Add_member_to_role-success | G8: role = "Application Administrator" | H8: user,opName,role,targetUser | I8: COUNT(*) >= 1 | J8: eventType = "MS-Entra-AuditLogs-RoleMgmt-Add_member_to_role-success" AND role = "Application Administrator" | K8: Filter | L8: 300
A9: PH_Rule_Azure_Entra_ID_User_Added_To_Exchange_Admin | B9: Azure Entra ID: User Added To Exchange Admin | C9: New ITDR (7.6.0) | D9: Filter | E9: MS-Entra-AuditLogs-RoleMgmt-Add_member_to_role-success | G9: role = "Exchange Administrator" | H9: user,opName,role,targetUser | I9: COUNT(*) >= 1 | J9: eventType = "MS-Entra-AuditLogs-RoleMgmt-Add_member_to_role-success" AND role = "Exchange Administrator" | K9: Filter | L9: 300
A10: PH_Rule_Azure_Entra_ID_User_Added_To_Global_Admin | B10: Azure Entra ID: User Added To Global Admin | C10: New ITDR (7.6.0) | D10: Filter | E10: MS-Entra-AuditLogs-RoleMgmt-Add_member_to_role-success | G10: role = "Global Administrator" | H10: user,opName,role,targetUser | I10: COUNT(*) >= 1 | J10: eventType = "MS-Entra-AuditLogs-RoleMgmt-Add_member_to_role-success" AND role = "Global Administrator" | K10: Filter | L10: 300
A11: PH_Rule_Azure_Entra_ID_User_Added_To_Privileged_Role_Admin | B11: Azure Entra ID: User Added To Privileged Role Admin | C11: New ITDR (7.6.0) | D11: Filter | E11: MS-Entra-AuditLogs-RoleMgmt-Add_member_to_role-success | G11: role = "Privileged Role Administrator" | H11: user,opName,role,targetUser | I11: COUNT(*) >= 1 | J11: eventType = "MS-Entra-AuditLogs-RoleMgmt-Add_member_to_role-success" AND role = "Privileged Role Administrator" | K11: Filter | L11: 300
A12: PH_Rule_Azure_Entra_ID_User_Added_To_Security_Admin | B12: Azure Entra ID: User Added To Security Admin | C12: New ITDR (7.6.0) | D12: Filter | E12: MS-Entra-AuditLogs-RoleMgmt-Add_member_to_role-success | G12: role = "Security Administrator" | H12: user,opName,role,targetUser | I12: COUNT(*) >= 1 | J12: eventType = "MS-Entra-AuditLogs-RoleMgmt-Add_member_to_role-success" AND role = "Security Administrator" | K12: Filter | L12: 300
A13: PH_Rule_Linux_etc_shadow_access | B13: Linux: /etc/shadow Access | C13: New ITDR (7.6.0) | D13: Filter | E13: LINUX_Auditd_PATH LINUX_Auditd_SYSCALL LINUX_PROCESS_EXEC | G13: (osObjName="/etc/shadow" OR command REGEXP ".*(?:/etc/shadow|unshadow).*") | H13: hostName,user,procName,command,osObjName | I13: COUNT(*) >= 1 | J13: eventType IN ("LINUX_Auditd_PATH","LINUX_Auditd_SYSCALL","LINUX_PROCESS_EXEC") AND (osObjName="/etc/shadow" OR command REGEXP ".*(?:/etc/shadow|unshadow).*") | K13: Filter | L13: 300
A14: PH_Rule_Linux_Root_Equivalent_Account_Command | B14: Linux: Attempt to Create or Modify a Root-Equivalent Account | C14: New ITDR (7.6.0) | D14: Filter | E14: LINUX_PROCESS_EXEC LINUX_Auditd_SYSCALL | G14: procName REGEXP "(?i).*(useradd|usermod)$" AND command REGEXP "(?i)\s*(?:-u\s*0|--uid(?:\s+|=)\s*0).*" | H14: hostName,user,procName,command | I14: COUNT(*) >= 1 | J14: eventType IN ("LINUX_PROCESS_EXEC","LINUX_Auditd_SYSCALL") AND procName REGEXP "(?i).*(useradd|usermod)$" AND command REGEXP "(?i)\s*(?:-u\s*0|--uid(?:\s+|=)\s*0).*" | K14: Filter | L14: 300
A15: PH_Rule_Linux_PAM_Configuration_Modified | B15: Linux: PAM Configuration Modified | C15: New ITDR (7.6.0) | D15: Filter | E15: FSM_LINUX_FILE_MODIFY | G15: targetOsObjName REGEXP "^/etc/pam\.conf$|^/etc/pam\.d/.*" | H15: hostName,user,targetOsObjName | I15: COUNT(*) >= 1 | J15: eventType = "FSM_LINUX_FILE_MODIFY" AND targetOsObjName REGEXP "^/etc/pam\.conf$|^/etc/pam\.d/.*" | K15: Filter | L15: 300
